<?xml version="1.0"?>
<robot name="sample_humanoid">
  <!-- This is a simplified humanoid robot model for simulation examples -->

  <!-- Base/Fixed link -->
  <link name="base_link">
    <inertial>
      <mass value="0.0001"/>
      <inertia ixx="0.0001" ixy="0" ixz="0" iyy="0.0001" iyz="0" izz="0.0001"/>
    </inertial>
  </link>

  <!-- Torso -->
  <link name="torso">
    <inertial>
      <mass value="5.0"/>
      <origin xyz="0 0 0.15"/>
      <inertia ixx="0.1" ixy="0" ixz="0" iyy="0.1" iyz="0" izz="0.05"/>
    </inertial>
    <visual>
      <origin xyz="0 0 0.15" rpy="0 0 0"/>
      <geometry>
        <cylinder length="0.3" radius="0.1"/>
      </geometry>
      <material name="grey">
        <color rgba="0.5 0.5 0.5 1"/>
      </material>
    </visual>
    <collision>
      <origin xyz="0 0 0.15" rpy="0 0 0"/>
      <geometry>
        <cylinder length="0.3" radius="0.1"/>
      </geometry>
    </collision>
  </link>

  <joint name="base_to_torso" type="fixed">
    <parent link="base_link"/>
    <child link="torso"/>
    <origin xyz="0 0 0.3" rpy="0 0 0"/>
  </joint>

  <!-- Head -->
  <link name="head">
    <inertial>
      <mass value="2.0"/>
      <origin xyz="0 0 0.1"/>
      <inertia ixx="0.01" ixy="0" ixz="0" iyy="0.01" iyz="0" izz="0.01"/>
    </inertial>
    <visual>
      <origin xyz="0 0 0.1" rpy="0 0 0"/>
      <geometry>
        <sphere radius="0.1"/>
      </geometry>
      <material name="skin">
        <color rgba="1 0.8 0.6 1"/>
      </material>
    </visual>
    <collision>
      <origin xyz="0 0 0.1" rpy="0 0 0"/>
      <geometry>
        <sphere radius="0.1"/>
      </geometry>
    </collision>
  </link>

  <joint name="neck_joint" type="revolute">
    <parent link="torso"/>
    <child link="head"/>
    <origin xyz="0 0 0.3" rpy="0 0 0"/>
    <axis xyz="0 1 0"/>
    <limit lower="-0.5" upper="0.5" effort="10" velocity="1.0"/>
  </joint>

  <!-- Left Arm -->
  <link name="left_upper_arm">
    <inertial>
      <mass value="1.0"/>
      <origin xyz="0 0 0.15"/>
      <inertia ixx="0.01" ixy="0" ixz="0" iyy="0.01" iyz="0" izz="0.001"/>
    </inertial>
    <visual>
      <origin xyz="0 0 0.15" rpy="0 0 0"/>
      <geometry>
        <cylinder length="0.3" radius="0.05"/>
      </geometry>
      <material name="grey"/>
    </visual>
    <collision>
      <origin xyz="0 0 0.15" rpy="0 0 0"/>
      <geometry>
        <cylinder length="0.3" radius="0.05"/>
      </geometry>
    </collision>
  </link>

  <joint name="left_shoulder_joint" type="revolute">
    <parent link="torso"/>
    <child link="left_upper_arm"/>
    <origin xyz="0.05 0.15 0.2" rpy="0 0 0"/>
    <axis xyz="0 1 0"/>
    <limit lower="-1.57" upper="1.57" effort="10" velocity="2.0"/>
  </joint>

  <link name="left_lower_arm">
    <inertial>
      <mass value="0.8"/>
      <inertia ixx="0.008" ixy="0" ixz="0" iyy="0.008" iyz="0" izz="0.001"/>
    </inertial>
    <visual>
      <origin xyz="0 0 0.12" rpy="0 0 0"/>
      <geometry>
        <cylinder length="0.24" radius="0.04"/>
      </geometry>
      <material name="grey"/>
    </visual>
    <collision>
      <origin xyz="0 0 0.12" rpy="0 0 0"/>
      <geometry>
        <cylinder length="0.24" radius="0.04"/>
      </geometry>
    </collision>
  </link>

  <joint name="left_elbow_joint" type="revolute">
    <parent link="left_upper_arm"/>
    <child link="left_lower_arm"/>
    <origin xyz="0 0 0.3" rpy="0 0 0"/>
    <axis xyz="0 1 0"/>
    <limit lower="-1.57" upper="1.57" effort="10" velocity="2.0"/>
  </joint>

  <link name="left_hand">
    <inertial>
      <mass value="0.3"/>
      <inertia ixx="0.001" ixy="0" ixz="0" iyy="0.001" iyz="0" izz="0.001"/>
    </inertial>
    <visual>
      <origin xyz="0 0 0.05" rpy="0 0 0"/>
      <geometry>
        <sphere radius="0.05"/>
      </geometry>
      <material name="skin"/>
    </visual>
    <collision>
      <origin xyz="0 0 0.05" rpy="0 0 0"/>
      <geometry>
        <sphere radius="0.05"/>
      </geometry>
    </collision>
  </link>

  <joint name="left_wrist_joint" type="revolute">
    <parent link="left_lower_arm"/>
    <child link="left_hand"/>
    <origin xyz="0 0 0.24" rpy="0 0 0"/>
    <axis xyz="0 1 0"/>
    <limit lower="-0.78" upper="0.78" effort="5" velocity="1.0"/>
  </joint>

  <!-- Right Arm -->
  <link name="right_upper_arm">
    <inertial>
      <mass value="1.0"/>
      <inertia ixx="0.01" ixy="0" ixz="0" iyy="0.01" iyz="0" izz="0.001"/>
    </inertial>
    <visual>
      <origin xyz="0 0 0.15" rpy="0 0 0"/>
      <geometry>
        <cylinder length="0.3" radius="0.05"/>
      </geometry>
      <material name="grey"/>
    </visual>
    <collision>
      <origin xyz="0 0 0.15" rpy="0 0 0"/>
      <geometry>
        <cylinder length="0.3" radius="0.05"/>
      </geometry>
    </collision>
  </link>

  <joint name="right_shoulder_joint" type="revolute">
    <parent link="torso"/>
    <child link="right_upper_arm"/>
    <origin xyz="0.05 -0.15 0.2" rpy="0 0 0"/>
    <axis xyz="0 1 0"/>
    <limit lower="-1.57" upper="1.57" effort="10" velocity="2.0"/>
  </joint>

  <link name="right_lower_arm">
    <inertial>
      <mass value="0.8"/>
      <inertia ixx="0.008" ixy="0" ixz="0" iyy="0.008" iyz="0" izz="0.001"/>
    </inertial>
    <visual>
      <origin xyz="0 0 0.12" rpy="0 0 0"/>
      <geometry>
        <cylinder length="0.24" radius="0.04"/>
      </geometry>
      <material name="grey"/>
    </visual>
    <collision>
      <origin xyz="0 0 0.12" rpy="0 0 0"/>
      <geometry>
        <cylinder length="0.24" radius="0.04"/>
      </geometry>
    </collision>
  </link>

  <joint name="right_elbow_joint" type="revolute">
    <parent link="right_upper_arm"/>
    <child link="right_lower_arm"/>
    <origin xyz="0 0 0.3" rpy="0 0 0"/>
    <axis xyz="0 1 0"/>
    <limit lower="-1.57" upper="1.57" effort="10" velocity="2.0"/>
  </joint>

  <link name="right_hand">
    <inertial>
      <mass value="0.3"/>
      <inertia ixx="0.001" ixy="0" ixz="0" iyy="0.001" iyz="0" izz="0.001"/>
    </inertial>
    <visual>
      <origin xyz="0 0 0.05" rpy="0 0 0"/>
      <geometry>
        <sphere radius="0.05"/>
      </geometry>
      <material name="skin"/>
    </visual>
    <collision>
      <origin xyz="0 0 0.05" rpy="0 0 0"/>
      <geometry>
        <sphere radius="0.05"/>
      </geometry>
    </collision>
  </link>

  <joint name="right_wrist_joint" type="revolute">
    <parent link="right_lower_arm"/>
    <child link="right_hand"/>
    <origin xyz="0 0 0.24" rpy="0 0 0"/>
    <axis xyz="0 1 0"/>
    <limit lower="-0.78" upper="0.78" effort="5" velocity="1.0"/>
  </joint>

  <!-- Left Leg -->
  <link name="left_hip">
    <inertial>
      <mass value="1.5"/>
      <inertia ixx="0.015" ixy="0" ixz="0" iyy="0.015" iyz="0" izz="0.005"/>
    </inertial>
    <visual>
      <origin xyz="0 0 -0.1" rpy="0 0 0"/>
      <geometry>
        <cylinder length="0.2" radius="0.08"/>
      </geometry>
      <material name="grey"/>
    </visual>
    <collision>
      <origin xyz="0 0 -0.1" rpy="0 0 0"/>
      <geometry>
        <cylinder length="0.2" radius="0.08"/>
      </geometry>
    </collision>
  </link>

  <joint name="left_hip_joint" type="revolute">
    <parent link="torso"/>
    <child link="left_hip"/>
    <origin xyz="-0.05 0.08 0" rpy="0 0 0"/>
    <axis xyz="1 0 0"/>
    <limit lower="-0.5" upper="0.5" effort="200" velocity="2.0"/>
  </joint>

  <link name="left_thigh">
    <inertial>
      <mass value="2.0"/>
      <origin xyz="0 0 -0.2"/>
      <inertia ixx="0.04" ixy="0" ixz="0" iyy="0.04" iyz="0" izz="0.01"/>
    </inertial>
    <visual>
      <origin xyz="0 0 -0.2" rpy="0 0 0"/>
      <geometry>
        <cylinder length="0.4" radius="0.06"/>
      </geometry>
      <material name="grey"/>
    </visual>
    <collision>
      <origin xyz="0 0 -0.2" rpy="0 0 0"/>
      <geometry>
        <cylinder length="0.4" radius="0.06"/>
      </geometry>
    </collision>
  </link>

  <joint name="left_knee_joint" type="revolute">
    <parent link="left_hip"/>
    <child link="left_thigh"/>
    <origin xyz="0 0 -0.2" rpy="0 0 0"/>
    <axis xyz="1 0 0"/>
    <limit lower="0" upper="2.0" effort="200" velocity="2.0"/>
  </joint>

  <link name="left_shin">
    <inertial>
      <mass value="1.5"/>
      <origin xyz="0 0 -0.2"/>
      <inertia ixx="0.03" ixy="0" ixz="0" iyy="0.03" iyz="0" izz="0.01"/>
    </inertial>
    <visual>
      <origin xyz="0 0 -0.2" rpy="0 0 0"/>
      <geometry>
        <cylinder length="0.4" radius="0.05"/>
      </geometry>
      <material name="grey"/>
    </visual>
    <collision>
      <origin xyz="0 0 -0.2" rpy="0 0 0"/>
      <geometry>
        <cylinder length="0.4" radius="0.05"/>
      </geometry>
    </collision>
  </link>

  <joint name="left_ankle_joint" type="revolute">
    <parent link="left_thigh"/>
    <child link="left_shin"/>
    <origin xyz="0 0 -0.4" rpy="0 0 0"/>
    <axis xyz="1 0 0"/>
    <limit lower="-0.5" upper="0.5" effort="100" velocity="1.0"/>
  </joint>

  <link name="left_foot">
    <inertial>
      <mass value="0.8"/>
      <inertia ixx="0.005" ixy="0" ixz="0" iyy="0.01" iyz="0" izz="0.01"/>
    </inertial>
    <visual>
      <origin xyz="0 0 -0.025" rpy="0 0 0"/>
      <geometry>
        <box size="0.2 0.1 0.05"/>
      </geometry>
      <material name="black">
        <color rgba="0.2 0.2 0.2 1"/>
      </material>
    </visual>
    <collision>
      <origin xyz="0 0 -0.025" rpy="0 0 0"/>
      <geometry>
        <box size="0.2 0.1 0.05"/>
      </geometry>
    </collision>
  </link>

  <joint name="left_foot_joint" type="fixed">
    <parent link="left_shin"/>
    <child link="left_foot"/>
    <origin xyz="0 0 -0.4" rpy="0 0 0"/>
  </joint>

  <!-- Right Leg -->
  <link name="right_hip">
    <inertial>
      <mass value="1.5"/>
      <inertia ixx="0.015" ixy="0" ixz="0" iyy="0.015" iyz="0" izz="0.005"/>
    </inertial>
    <visual>
      <origin xyz="0 0 -0.1" rpy="0 0 0"/>
      <geometry>
        <cylinder length="0.2" radius="0.08"/>
      </geometry>
      <material name="grey"/>
    </visual>
    <collision>
      <origin xyz="0 0 -0.1" rpy="0 0 0"/>
      <geometry>
        <cylinder length="0.2" radius="0.08"/>
      </geometry>
    </collision>
  </link>

  <joint name="right_hip_joint" type="revolute">
    <parent link="torso"/>
    <child link="right_hip"/>
    <origin xyz="-0.05 -0.08 0" rpy="0 0 0"/>
    <axis xyz="1 0 0"/>
    <limit lower="-0.5" upper="0.5" effort="200" velocity="2.0"/>
  </joint>

  <link name="right_thigh">
    <inertial>
      <mass value="2.0"/>
      <origin xyz="0 0 -0.2"/>
      <inertia ixx="0.04" ixy="0" ixz="0" iyy="0.04" iyz="0" izz="0.01"/>
    </inertial>
    <visual>
      <origin xyz="0 0 -0.2" rpy="0 0 0"/>
      <geometry>
        <cylinder length="0.4" radius="0.06"/>
      </geometry>
      <material name="grey"/>
    </visual>
    <collision>
      <origin xyz="0 0 -0.2" rpy="0 0 0"/>
      <geometry>
        <cylinder length="0.4" radius="0.06"/>
      </geometry>
    </collision>
  </link>

  <joint name="right_knee_joint" type="revolute">
    <parent link="right_hip"/>
    <child link="right_thigh"/>
    <origin xyz="0 0 -0.2" rpy="0 0 0"/>
    <axis xyz="1 0 0"/>
    <limit lower="0" upper="2.0" effort="200" velocity="2.0"/>
  </joint>

  <link name="right_shin">
    <inertial>
      <mass value="1.5"/>
      <origin xyz="0 0 -0.2"/>
      <inertia ixx="0.03" ixy="0" ixz="0" iyy="0.03" iyz="0" izz="0.01"/>
    </inertial>
    <visual>
      <origin xyz="0 0 -0.2" rpy="0 0 0"/>
      <geometry>
        <cylinder length="0.4" radius="0.05"/>
      </geometry>
      <material name="grey"/>
    </visual>
    <collision>
      <origin xyz="0 0 -0.2" rpy="0 0 0"/>
      <geometry>
        <cylinder length="0.4" radius="0.05"/>
      </geometry>
    </collision>
  </link>

  <joint name="right_ankle_joint" type="revolute">
    <parent link="right_thigh"/>
    <child link="right_shin"/>
    <origin xyz="0 0 -0.4" rpy="0 0 0"/>
    <axis xyz="1 0 0"/>
    <limit lower="-0.5" upper="0.5" effort="100" velocity="1.0"/>
  </joint>

  <link name="right_foot">
    <inertial>
      <mass value="0.8"/>
      <inertia ixx="0.005" ixy="0" ixz="0" iyy="0.01" iyz="0" izz="0.01"/>
    </inertial>
    <visual>
      <origin xyz="0 0 -0.025" rpy="0 0 0"/>
      <geometry>
        <box size="0.2 0.1 0.05"/>
      </geometry>
      <material name="black"/>
    </visual>
    <collision>
      <origin xyz="0 0 -0.025" rpy="0 0 0"/>
      <geometry>
        <box size="0.2 0.1 0.05"/>
      </geometry>
    </collision>
  </link>

  <joint name="right_foot_joint" type="fixed">
    <parent link="right_shin"/>
    <child link="right_foot"/>
    <origin xyz="0 0 -0.4" rpy="0 0 0"/>
  </joint>

  <!-- ROS Control interface -->
  <ros2_control name="GazeboSystem" type="system">
    <hardware>
      <plugin>gazebo_ros2_control/GazeboSystem</plugin>
    </hardware>

    <joint name="left_shoulder_joint">
      <command_interface name="position"/>
      <state_interface name="position"/>
      <state_interface name="velocity"/>
      <state_interface name="effort"/>
    </joint>

    <joint name="left_elbow_joint">
      <command_interface name="position"/>
      <state_interface name="position"/>
      <state_interface name="velocity"/>
      <state_interface name="effort"/>
    </joint>

    <joint name="right_shoulder_joint">
      <command_interface name="position"/>
      <state_interface name="position"/>
      <state_interface name="velocity"/>
      <state_interface name="effort"/>
    </joint>

    <joint name="right_elbow_joint">
      <command_interface name="position"/>
      <state_interface name="position"/>
      <state_interface name="velocity"/>
      <state_interface name="effort"/>
    </joint>

    <joint name="left_hip_joint">
      <command_interface name="position"/>
      <state_interface name="position"/>
      <state_interface name="velocity"/>
      <state_interface name="effort"/>
    </joint>

    <joint name="left_knee_joint">
      <command_interface name="position"/>
      <state_interface name="position"/>
      <state_interface name="velocity"/>
      <state_interface name="effort"/>
    </joint>

    <joint name="left_ankle_joint">
      <command_interface name="position"/>
      <state_interface name="position"/>
      <state_interface name="velocity"/>
      <state_interface name="effort"/>
    </joint>

    <joint name="right_hip_joint">
      <command_interface name="position"/>
      <state_interface name="position"/>
      <state_interface name="velocity"/>
      <state_interface name="effort"/>
    </joint>

    <joint name="right_knee_joint">
      <command_interface name="position"/>
      <state_interface name="position"/>
      <state_interface name="velocity"/>
      <state_interface name="effort"/>
    </joint>

    <joint name="right_ankle_joint">
      <command_interface name="position"/>
      <state_interface name="position"/>
      <state_interface name="velocity"/>
      <state_interface name="effort"/>
    </joint>
  </ros2_control>
</robot>